<?xml version="1.0" encoding="utf-8"?>
<!--
This URDF was automatically created by SolidWorks to URDF Exporter! Originally created by Stephen Brawner (brawner@gmail.com)
Commit Version: 1.6.0-4-g7f85cfe  Build Version: 1.6.7995.38578
For more information, please see http://wiki.ros.org/sw_urdf_exporter
-->
<robot name="model_H">
	<link name="base_link">
		<inertial>
			<origin xyz="0.0096 0.0005 0.1157" rpy="0 0 0" />
			<mass value="2.503" />
			<inertia ixx="0.0584" ixy="0" ixz="0.0035" iyy="0.0536" iyz="0.0002" izz="0.0099" />
		</inertial>
		<visual>
			<origin xyz="0 0 0" rpy="0 0 0" />
			<geometry>
				<mesh filename="package://livelybot_urdf/meshes/base_link.STL" />
			</geometry>
			<material name="">
				<color rgba="0.75294 0.75294 0.75294 1" />
			</material>
		</visual>
		<collision>
			<origin xyz="0 0 0" rpy="0 0 0" />
			<geometry>
				<mesh filename="package://livelybot_urdf/meshes/base_link.STL" />
			</geometry>
		</collision>
	</link>
	<link name="r_hip_yaw_link">
		<inertial>
			<origin xyz="-0.0594 0 -0.0436" rpy="0 0 0" />
			<mass value="0.3593" />
			<inertia ixx="0.0009" ixy="0" ixz="0.001" iyy="0.0022" iyz="0" izz="0.0015" />
		</inertial>
		<visual>
			<origin xyz="0 0 0" rpy="0 0 0" />
			<geometry>
				<mesh filename="package://livelybot_urdf/meshes/r_hip_yaw_link.STL" />
			</geometry>
			<material name="">
				<color rgba="0.75294 0.75294 0.75294 1" />
			</material>
		</visual>
		<collision>
			<origin xyz="0 0 0" rpy="0 0 0" />
			<geometry>
				<mesh filename="package://livelybot_urdf/meshes/r_hip_yaw_link.STL" />
			</geometry>
		</collision>
	</link>
	<joint name="r_hip_yaw_joint" type="revolute">
		<origin xyz="0 -0.075 0" rpy="0 0 0" />
		<parent link="base_link" />
		<child link="r_hip_yaw_link" />
		<axis xyz="0 0 1" />
		<limit lower="-3.14" upper="3.14" effort="21" velocity="21" />
	</joint>
	<link name="r_hip_roll_link">
		<inertial>
			<origin xyz="0.0366 0.0002 0.0004" rpy="0 0 0" />
			<mass value="0.7306" />
			<inertia ixx="0.0014" ixy="0" ixz="0" iyy="0.0003" iyz="0" izz="0.0014" />
		</inertial>
		<visual>
			<origin xyz="0 0 0" rpy="0 0 0" />
			<geometry>
				<mesh filename="package://livelybot_urdf/meshes/r_hip_roll_link.STL" />
			</geometry>
			<material name="">
				<color rgba="0.75294 0.75294 0.75294 1" />
			</material>
		</visual>
		<collision>
			<origin xyz="0 0 0" rpy="0 0 0" />
			<geometry>
				<mesh filename="package://livelybot_urdf/meshes/r_hip_roll_link.STL" />
			</geometry>
		</collision>
	</link>
	<joint name="r_hip_roll_joint" type="revolute">
		<origin xyz="-0.037 0 -0.049" rpy="0 0 0" />
		<parent link="r_hip_yaw_link" />
		<child link="r_hip_roll_link" />
		<axis xyz="1 0 0" />
		<limit lower="-3.14" upper="3.14" effort="21" velocity="21" />
	</joint>
	<link name="r_thigh_link">
		<inertial>
			<origin xyz="0.0043 0.0024 -0.0565" rpy="0 0 0" />
			<mass value="0.10988" />
			<inertia ixx="0.0006751" ixy="4E-07" ixz="-4.96E-05" iyy="0.0006779" iyz="-3E-07" izz="3.66E-05" />
		</inertial>
		<visual>
			<origin xyz="0 0 0" rpy="0 0 0" />
			<geometry>
				<mesh filename="package://livelybot_urdf/meshes/r_thigh_link.STL" />
			</geometry>
			<material name="">
				<color rgba="0.75294 0.75294 0.75294 1" />
			</material>
		</visual>
		<collision>
			<origin xyz="0 0 0" rpy="0 0 0" />
			<geometry>
				<mesh filename="package://livelybot_urdf/meshes/r_thigh_link.STL" />
			</geometry>
		</collision>
	</link>
	<joint name="r_thigh_joint" type="revolute">
		<origin xyz="0.039 0 0" rpy="0 0 0" />
		<parent link="r_hip_roll_link" />
		<child link="r_thigh_link" />
		<axis xyz="0 1 0" />
		<limit lower="-3.14" upper="3.14" effort="21" velocity="21" />
	</joint>
	<link name="r_calf_link">
		<inertial>
			<origin xyz="0.0040818 -0.0007633 -0.0728549" rpy="0 0 0" />
			<mass value="0.5043936" />
			<inertia ixx="0.0034667" ixy="-1.4E-06" ixz="-0.0001407" iyy="0.0035012" iyz="2.43E-05" izz="0.0001659" />
		</inertial>
		<visual>
			<origin xyz="0 0 0" rpy="0 0 0" />
			<geometry>
				<mesh filename="package://livelybot_urdf/meshes/r_calf_link.STL" />
			</geometry>
			<material name="">
				<color rgba="0.75294 0.75294 0.75294 1" />
			</material>
		</visual>
		<collision>
			<origin xyz="0 0 0" rpy="0 0 0" />
			<geometry>
				<mesh filename="package://livelybot_urdf/meshes/r_calf_link.STL" />
			</geometry>
		</collision>
	</link>
	<joint name="r_calf_joint" type="revolute">
		<origin xyz="0.011329 0 -0.14915" rpy="0 0 0" />
		<parent link="r_thigh_link" />
		<child link="r_calf_link" />
		<axis xyz="0 1 0" />
		<limit lower="-3.14" upper="3.14" effort="21" velocity="21" />
	</joint>
	<link name="r_ankle_pitch_link">
		<inertial>
			<origin xyz="0 -0.00081942 0" rpy="0 0 0" />
			<mass value="0.0088647" />
			<inertia ixx="2E-07" ixy="0" ixz="0" iyy="1E-06" iyz="0" izz="1E-06" />
		</inertial>
		<visual>
			<origin xyz="0 0 0" rpy="0 0 0" />
			<geometry>
				<mesh filename="package://livelybot_urdf/meshes/r_ankle_pitch_link.STL" />
			</geometry>
			<material name="">
				<color rgba="0.89804 0.91765 0.92941 1" />
			</material>
		</visual>
		<collision>
			<origin xyz="0 0 0" rpy="0 0 0" />
			<geometry>
				<mesh filename="package://livelybot_urdf/meshes/r_ankle_pitch_link.STL" />
			</geometry>
		</collision>
	</link>
	<joint name="r_ankle_pitch_joint" type="revolute">
		<origin xyz="0 0 -0.16" rpy="0 0 0" />
		<parent link="r_calf_link" />
		<child link="r_ankle_pitch_link" />
		<axis xyz="0 1 0" />
		<limit lower="-3.14" upper="3.14" effort="21" velocity="21" />
	</joint>
	<link name="r_ankle_roll_link">
		<inertial>
			<origin xyz="0.0244038 -1.5E-06 -0.0187171" rpy="0 0 0" />
			<mass value="0.1803263" />
			<inertia ixx="0.0001439" ixy="0" ixz="-0.0001053" iyy="0.0005162" iyz="0" izz="0.0005037" />
		</inertial>
		<visual>
			<origin xyz="0 0 0" rpy="0 0 0" />
			<geometry>
				<mesh filename="package://livelybot_urdf/meshes/r_ankle_roll_link.STL" />
			</geometry>
			<material name="">
				<color rgba="0.75294 0.75294 0.75294 1" />
			</material>
		</visual>
		<collision>
			<origin xyz="0 0 0" rpy="0 0 0" />
			<geometry>
				<mesh filename="package://livelybot_urdf/meshes/r_ankle_roll_link.STL" />
			</geometry>
		</collision>
	</link>
	<joint name="r_ankle_roll_joint" type="revolute">
		<origin xyz="0 -0.00081906 0" rpy="0 0 0" />
		<parent link="r_ankle_pitch_link" />
		<child link="r_ankle_roll_link" />
		<axis xyz="1 0 0" />
		<limit lower="-3.14" upper="3.14" effort="21" velocity="21" />
	</joint>
	<link name="l_hip_yaw_link">
		<inertial>
			<origin xyz="-0.0593709 0 -0.0436487" rpy="0 0 0" />
			<mass value="0.3593216" />
			<inertia ixx="0.0008659" ixy="0" ixz="0.0010182" iyy="0.0022471" iyz="0" izz="0.0014877" />
		</inertial>
		<visual>
			<origin xyz="0 0 0" rpy="0 0 0" />
			<geometry>
				<mesh filename="package://livelybot_urdf/meshes/l_hip_yaw_link.STL" />
			</geometry>
			<material name="">
				<color rgba="0.75294 0.75294 0.75294 1" />
			</material>
		</visual>
		<collision>
			<origin xyz="0 0 0" rpy="0 0 0" />
			<geometry>
				<mesh filename="package://livelybot_urdf/meshes/l_hip_yaw_link.STL" />
			</geometry>
		</collision>
	</link>
	<joint name="l_hip_yaw_joint" type="revolute">
		<origin xyz="0 0.075 0" rpy="0 0 0" />
		<parent link="base_link" />
		<child link="l_hip_yaw_link" />
		<axis xyz="0 0 1" />
		<limit lower="-3.14" upper="3.14" effort="21" velocity="21" />
	</joint>
	<link name="l_hip_roll_link">
		<inertial>
			<origin xyz="0.0363921 0.0008346 0.0004071" rpy="0 0 0" />
			<mass value="0.73062" />
			<inertia ixx="0.0014025" ixy="2.05E-05" ixz="5.7E-06" iyy="0.0012475" iyz="2E-07" izz="0.0024131" />
		</inertial>
		<visual>
			<origin xyz="0 0 0" rpy="0 0 0" />
			<geometry>
				<mesh filename="package://livelybot_urdf/meshes/l_hip_roll_link.STL" />
			</geometry>
			<material name="">
				<color rgba="0.75294 0.75294 0.75294 1" />
			</material>
		</visual>
		<collision>
			<origin xyz="0 0 0" rpy="0 0 0" />
			<geometry>
				<mesh filename="package://livelybot_urdf/meshes/l_hip_roll_link.STL" />
			</geometry>
		</collision>
	</link>
	<joint name="l_hip_roll_joint" type="revolute">
		<origin xyz="-0.037 0 -0.049" rpy="0 0 0" />
		<parent link="l_hip_yaw_link" />
		<child link="l_hip_roll_link" />
		<axis xyz="1 0 0" />
		<limit lower="-3.14" upper="3.14" effort="21" velocity="21" />
	</joint>
	<link name="l_thigh_link">
		<inertial>
			<origin xyz="0.0045462 -0.0023864 -0.0566449" rpy="0 0 0" />
			<mass value="0.1098811" />
			<inertia ixx="0.0006773" ixy="0" ixz="-5.17E-05" iyy="0.0006804" iyz="1E-07" izz="3.69E-05" />
		</inertial>
		<visual>
			<origin xyz="0 0 0" rpy="0 0 0" />
			<geometry>
				<mesh filename="package://livelybot_urdf/meshes/l_thigh_link.STL" />
			</geometry>
			<material name="">
				<color rgba="0.75294 0.75294 0.75294 1" />
			</material>
		</visual>
		<collision>
			<origin xyz="0 0 0" rpy="0 0 0" />
			<geometry>
				<mesh filename="package://livelybot_urdf/meshes/l_thigh_link.STL" />
			</geometry>
		</collision>
	</link>
	<joint name="l_thigh_joint" type="revolute">
		<origin xyz="0.039 0 0" rpy="0 0 0" />
		<parent link="l_hip_roll_link" />
		<child link="l_thigh_link" />
		<axis xyz="0 1 0" />
		<limit lower="-3.14" upper="3.14" effort="21" velocity="21" />
	</joint>
	<link name="l_calf_link">
		<inertial>
			<origin xyz="0.0040818 1.4E-06 -0.0728549" rpy="0 0 0" />
			<mass value="0.5043936" />
			<inertia ixx="0.0034664" ixy="0" ixz="-0.0001407" iyy="0.0035012" iyz="5.6E-06" izz="0.0001656" />
		</inertial>
		<visual>
			<origin xyz="0 0 0" rpy="0 0 0" />
			<geometry>
				<mesh filename="package://livelybot_urdf/meshes/l_calf_link.STL" />
			</geometry>
			<material name="">
				<color rgba="0.75294 0.75294 0.75294 1" />
			</material>
		</visual>
		<collision>
			<origin xyz="0 0 0" rpy="0 0 0" />
			<geometry>
				<mesh filename="package://livelybot_urdf/meshes/l_calf_link.STL" />
			</geometry>
		</collision>
	</link>
	<joint name="l_calf_link" type="revolute">
		<origin xyz="0.012 0 -0.14952" rpy="0 0 0" />
		<parent link="l_thigh_link" />
		<child link="l_calf_link" />
		<axis xyz="0 1 0" />
		<limit lower="-3.14" upper="3.14" effort="21" velocity="21" />
	</joint>
	<link name="l_ankle_pitch_link">
		<inertial>
			<origin xyz="0 0 0" rpy="0 0 0" />
			<mass value="0.0088647" />
			<inertia ixx="2E-07" ixy="0" ixz="0" iyy="1E-06" iyz="0" izz="1E-06" />
		</inertial>
		<visual>
			<origin xyz="0 0 0" rpy="0 0 0" />
			<geometry>
				<mesh filename="package://livelybot_urdf/meshes/l_ankle_pitch_link.STL" />
			</geometry>
			<material name="">
				<color rgba="0.89804 0.91765 0.92941 1" />
			</material>
		</visual>
		<collision>
			<origin xyz="0 0 0" rpy="0 0 0" />
			<geometry>
				<mesh filename="package://livelybot_urdf/meshes/l_ankle_pitch_link.STL" />
			</geometry>
		</collision>
	</link>
	<joint name="l_ankle_pitch_joint" type="revolute">
		<origin xyz="0 0 -0.16" rpy="0 0 0" />
		<parent link="l_calf_link" />
		<child link="l_ankle_pitch_link" />
		<axis xyz="0 1 0" />
		<limit lower="-3.14" upper="3.14" effort="21" velocity="21" />
	</joint>
	<link name="l_ankle_roll_link">
		<inertial>
			<origin xyz="0.0237112 0 -0.0185693" rpy="0 0 0" />
			<mass value="0.1749744" />
			<inertia ixx="0.0001392" ixy="0" ixz="-9.94E-05" iyy="0.0004925" iyz="0" izz="0.0004813" />
		</inertial>
		<visual>
			<origin xyz="0 0 0" rpy="0 0 0" />
			<geometry>
				<mesh filename="package://livelybot_urdf/meshes/l_ankle_roll_link.STL" />
			</geometry>
			<material name="">
				<color rgba="0.75294 0.75294 0.75294 1" />
			</material>
		</visual>
		<collision>
			<origin xyz="0 0 0" rpy="0 0 0" />
			<geometry>
				<mesh filename="package://livelybot_urdf/meshes/l_ankle_roll_link.STL" />
			</geometry>
		</collision>
	</link>
	<joint name="l_ankle_roll_joint" type="revolute">
		<origin xyz="0 0 0" rpy="0 0 0" />
		<parent link="l_ankle_pitch_link" />
		<child link="l_ankle_roll_link" />
		<axis xyz="1 0 0" />
		<limit lower="-3.14" upper="3.14" effort="21" velocity="21" />
	</joint>
	<link name="r_shoulder_pitch_link">
		<inertial>
			<origin xyz="0.0020923 -0.0251964 0" rpy="0 0 0" />
			<mass value="0.2129671" />
			<inertia ixx="0.000206" ixy="-8.3E-06" ixz="0" iyy="5.86E-05" iyz="0" izz="0.0002099" />
		</inertial>
		<visual>
			<origin xyz="0 0 0" rpy="0 0 0" />
			<geometry>
				<mesh filename="package://livelybot_urdf/meshes/r_shoulder_pitch_link.STL" />
			</geometry>
			<material name="">
				<color rgba="0.75294 0.75294 0.75294 1" />
			</material>
		</visual>
		<collision>
			<origin xyz="0 0 0" rpy="0 0 0" />
			<geometry>
				<mesh filename="package://livelybot_urdf/meshes/r_shoulder_pitch_link.STL" />
			</geometry>
		</collision>
	</link>
	<joint name="r_shoulder_pitch_joint" type="revolute">
		<origin xyz="-0.00238 -0.0855 0.2045" rpy="0 0 0" />
		<parent link="base_link" />
		<child link="r_shoulder_pitch_link" />
		<axis xyz="0 1 0" />
		<limit lower="-3.14" upper="3.14" effort="21" velocity="21" />
	</joint>
	<link name="r_shoulder_roll_link">
		<inertial>
			<origin xyz="-0.0154214 0 -0.0421688" rpy="0 0 0" />
			<mass value="0.2549246" />
			<inertia ixx="0.0005765" ixy="0" ixz="0.0002024" iyy="0.0006886" iyz="0" izz="0.0001687" />
		</inertial>
		<visual>
			<origin xyz="0 0 0" rpy="0 0 0" />
			<geometry>
				<mesh filename="package://livelybot_urdf/meshes/r_shoulder_roll_link.STL" />
			</geometry>
			<material name="">
				<color rgba="0.75294 0.75294 0.75294 1" />
			</material>
		</visual>
		<collision>
			<origin xyz="0 0 0" rpy="0 0 0" />
			<geometry>
				<mesh filename="package://livelybot_urdf/meshes/r_shoulder_roll_link.STL" />
			</geometry>
		</collision>
	</link>
	<joint name="r_shoulder_roll_joint" type="revolute">
		<origin xyz="0.024 -0.028574 0" rpy="0 0 0" />
		<parent link="r_shoulder_pitch_link" />
		<child link="r_shoulder_roll_link" />
		<axis xyz="1 0 0" />
		<limit lower="-3.14" upper="3.14" effort="21" velocity="21" />
	</joint>
	<link name="r_shoulder_yaw_link">
		<inertial>
			<origin xyz="0 -0.0014711 -0.0825374" rpy="0 0 0" />
			<mass value="0.2397004" />
			<inertia ixx="0.0018366" ixy="0" ixz="0" iyy="0.0018331" iyz="3.06E-05" izz="5.73E-05" />
		</inertial>
		<visual>
			<origin xyz="0 0 0" rpy="0 0 0" />
			<geometry>
				<mesh filename="package://livelybot_urdf/meshes/r_shoulder_yaw_link.STL" />
			</geometry>
			<material name="">
				<color rgba="0.75294 0.75294 0.75294 1" />
			</material>
		</visual>
		<collision>
			<origin xyz="0 0 0" rpy="0 0 0" />
			<geometry>
				<mesh filename="package://livelybot_urdf/meshes/r_shoulder_yaw_link.STL" />
			</geometry>
		</collision>
	</link>
	<joint name="r_shoulder_yaw_joint" type="revolute">
		<origin xyz="-0.024 0 -0.071" rpy="0 0 0" />
		<parent link="r_shoulder_roll_link" />
		<child link="r_shoulder_yaw_link" />
		<axis xyz="0 0 1" />
		<limit lower="-3.14" upper="3.14" effort="21" velocity="21" />
	</joint>
	<link name="r_elbow_link">
		<inertial>
			<origin xyz="0.0294356 0.0093745 0" rpy="0 0 0" />
			<mass value="0.0490686" />
			<inertia ixx="1.46E-05" ixy="3.39E-05" ixz="0" iyy="0.0001645" iyz="0" izz="0.0001744" />
		</inertial>
		<visual>
			<origin xyz="0 0 0" rpy="0 0 0" />
			<geometry>
				<mesh filename="package://livelybot_urdf/meshes/r_elbow_link.STL" />
			</geometry>
			<material name="">
				<color rgba="0.75294 0.75294 0.75294 1" />
			</material>
		</visual>
		<collision>
			<origin xyz="0 0 0" rpy="0 0 0" />
			<geometry>
				<mesh filename="package://livelybot_urdf/meshes/r_elbow_link.STL" />
			</geometry>
		</collision>
	</link>
	<joint name="r_elbow_joint" type="revolute">
		<origin xyz="0.010624 -0.024 -0.094" rpy="0 0 0" />
		<parent link="r_shoulder_yaw_link" />
		<child link="r_elbow_link" />
		<axis xyz="0 1 0" />
		<limit lower="-3.14" upper="3.14" effort="21" velocity="21" />
	</joint>
	<link name="l_shoulder_pitch_link">
		<inertial>
			<origin xyz="0.001691 0 -0.0289883" rpy="0 0 0" />
			<mass value="0.2085303" />
			<inertia ixx="0.0002429" ixy="0" ixz="-8.8E-06" iyy="0.0002465" iyz="0" izz="5.51E-05" />
		</inertial>
		<visual>
			<origin xyz="0 0 0" rpy="0 0 0" />
			<geometry>
				<mesh filename="package://livelybot_urdf/meshes/l_shoulder_pitch_link.STL" />
			</geometry>
			<material name="">
				<color rgba="0.75294 0.75294 0.75294 1" />
			</material>
		</visual>
		<collision>
			<origin xyz="0 0 0" rpy="0 0 0" />
			<geometry>
				<mesh filename="package://livelybot_urdf/meshes/l_shoulder_pitch_link.STL" />
			</geometry>
		</collision>
	</link>
	<joint name="l_shoulder_pitch_joint" type="revolute">
		<origin xyz="-0.00237999999999805 0.0854999999999995 0.204500000000003" rpy="1.5707963267949 0 0" />
		<parent link="base_link" />
		<child link="l_shoulder_pitch_link" />
		<axis xyz="0 0 -1" />
		<limit lower="-3.14" upper="3.14" effort="21" velocity="21" />
	</joint>
	<link name="l_shoulder_roll_link">
		<inertial>
			<origin xyz="-0.0154214 0 -0.0421688" rpy="0 0 0" />
			<mass value="0.2549246" />
			<inertia ixx="0.0005765" ixy="0" ixz="0.0002024" iyy="0.0006886" iyz="0" izz="0.0001687" />
		</inertial>
		<visual>
			<origin xyz="0 0 0" rpy="0 0 0" />
			<geometry>
				<mesh filename="package://livelybot_urdf/meshes/l_shoulder_roll_link.STL" />
			</geometry>
			<material name="">
				<color rgba="0.75294 0.75294 0.75294 1" />
			</material>
		</visual>
		<collision>
			<origin xyz="0 0 0" rpy="0 0 0" />
			<geometry>
				<mesh filename="package://livelybot_urdf/meshes/l_shoulder_roll_link.STL" />
			</geometry>
		</collision>
	</link>
	<joint name="l_shoulder_roll_joint" type="revolute">
		<origin xyz="0.024 0 -0.032" rpy="-1.5708 0 0" />
		<parent link="l_shoulder_pitch_link" />
		<child link="l_shoulder_roll_link" />
		<axis xyz="1 0 0" />
		<limit lower="-3.14" upper="3.14" effort="21" velocity="21" />
	</joint>
	<link name="l_shoulder_yaw_link">
		<inertial>
			<origin xyz="0 0.0014711 -0.08002" rpy="0 0 0" />
			<mass value="0.2397004" />
			<inertia ixx="0.0017385" ixy="0" ixz="0" iyy="0.001735" iyz="-2.98E-05" izz="5.73E-05" />
		</inertial>
		<visual>
			<origin xyz="0 0 0" rpy="0 0 0" />
			<geometry>
				<mesh filename="package://livelybot_urdf/meshes/l_shoulder_yaw_link.STL" />
			</geometry>
			<material name="">
				<color rgba="0.75294 0.75294 0.75294 1" />
			</material>
		</visual>
		<collision>
			<origin xyz="0 0 0" rpy="0 0 0" />
			<geometry>
				<mesh filename="package://livelybot_urdf/meshes/l_shoulder_yaw_link.STL" />
			</geometry>
		</collision>
	</link>
	<joint name="l_shoulder_yaw_joint" type="revolute">
		<origin xyz="-0.024 0 -0.071" rpy="0 0 0" />
		<parent link="l_shoulder_roll_link" />
		<child link="l_shoulder_yaw_link" />
		<axis xyz="0 0 1" />
		<limit lower="-3.14" upper="3.14" effort="21" velocity="21" />
	</joint>
	<link name="l_elbow_link">
		<inertial>
			<origin xyz="0.0400599 -0.0093745 0" rpy="0 0 0" />
			<mass value="0.0490686" />
			<inertia ixx="1.46E-05" ixy="-3.88E-05" ixz="0" iyy="0.0002007" iyz="0" izz="0.0002106" />
		</inertial>
		<visual>
			<origin xyz="0 0 0" rpy="0 0 0" />
			<geometry>
				<mesh filename="package://livelybot_urdf/meshes/l_elbow_link.STL" />
			</geometry>
			<material name="">
				<color rgba="0.75294 0.75294 0.75294 1" />
			</material>
		</visual>
		<collision>
			<origin xyz="0 0 0" rpy="0 0 0" />
			<geometry>
				<mesh filename="package://livelybot_urdf/meshes/l_elbow_link.STL" />
			</geometry>
		</collision>
	</link>
	<joint name="l_elbow_joint" type="revolute">
		<origin xyz="0 0.024 -0.091483" rpy="0 0 0" />
		<parent link="l_shoulder_yaw_link" />
		<child link="l_elbow_link" />
		<axis xyz="0 1 0" />
		<limit lower="-3.14" upper="3.14" effort="21" velocity="21" />
	</joint>
</robot>
